<?xml version='1.0' encoding='ASCII'?>
<robot name="test_fetch">
  <link name="base_link"/>
  <joint name="base_link_palm" type="fixed">
    <origin rpy="0 0.00000000 0.00000000"/>
    <parent link="base_link"/>
    <child link="palm"/>
  </joint>
  <link name="palm">
    <visual>
      <geometry>
        <mesh filename="file:///root/GraspIt2URDF/data/test_fetch/palm.stl" scale="1.00000000 1.00000000 1.00000000"/>
      </geometry>
    </visual>
    <inertial>
      <mass value="1.00000000"/>
      <inertia ixx="2.0000e-21" ixy="0.0000e+00" ixz="-0.0000e+00" iyy="2.0000e-21" iyz="0.0000e+00" izz="3.0000e-21"/>
      <origin xyz="0.00007247 -0.00000000 0.00000167"/>
    </inertial>
  </link>



  <link name="l_gripper_finger_link"/>
  <link name="l_gripper_finger_link_joint"/>
  
  <joint name="palm_l_gripper_finger_link_joint" type="prismatic">
    <origin rpy="0 0.00000000 0.00000000" xyz="0 0 0"/>
    <parent link="palm"/>
    <child link="l_gripper_finger_link_joint"/>
    <limit effort="50000.00000000" lower="0.0" upper="-0.363604443068" velocity="0.52333333"/>
    <axis xyz="0 0 -1"/>
  </joint>

  <joint name="l_gripper_finger_link_joint_l_gripper_finger_link" type="fixed">
    <origin rpy="0.00000000 0.00000000 0.00000000" xyz="0.00000000 0.00000000 0.00000000"/>
    <parent link="l_gripper_finger_link_joint"/>
    <child link="l_gripper_finger_link"/>
  </joint>




</robot>
